Workbook
Name e_semana: 'Entrada semanal'!$A$5:$A$404
Name e_canal: 'Entrada semanal'!$B$5:$B$404
Name e_invest: 'Entrada semanal'!$C$5:$C$404
Name e_leads: 'Entrada semanal'!$D$5:$D$404
Name e_qual: 'Entrada semanal'!$E$5:$E$404
Name e_agend: 'Entrada semanal'!$F$5:$F$404
Name e_comp: 'Entrada semanal'!$G$5:$G$404
Name e_fech: 'Entrada semanal'!$H$5:$H$404
Name e_receita: 'Entrada semanal'!$I$5:$I$404

Sheet Como usar
A2: Dashboard da clínica: como usar
A3: 10 minutos toda segunda-feira. Você só digita nas células douradas.
A5: Passo | B5: O que fazer
A6: 1 | B6: Toda segunda-feira, abra a aba “Entrada semanal”.
A7: 2 | B7: Adicione uma linha por canal com a data de início da semana (a segunda-feira) e escolha o canal na lista.
A8: 3 | B8: Preencha só as células douradas: investimento em anúncios, leads, qualificados, agendados, compareceram, fechados e receita fechada.
A9: 4 | B9: Abra o “Dashboard”: última semana, média de 4 semanas e mês até agora se atualizam sozinhos. Verde, amarelo e vermelho comparam com as suas “Metas”.
A10: 5 | B10: Em “Por canal”, veja qual canal traz receita, não só leads. Anote uma decisão para a semana.
A12: Legenda
B13: Célula dourada: você preenche.
B14: Célula branca: fórmula. Não apague: é ela que calcula o dashboard.
A15: – | B15: Traço: não dá para calcular ainda (divisão por zero, por exemplo 0 fechados).
A17: Definições
A18: Lead | B18: Qualquer contato novo: mensagem, ligação ou formulário.
A19: Qualificado | B19: Lead com perfil e interesse real para a clínica (respondeu às perguntas de qualificação).
A20: Agendado | B20: Avaliação marcada na semana.
A21: Compareceu | B21: Paciente que veio à avaliação.
A22: Fechado | B22: Paciente que aprovou o plano de tratamento.
A23: Receita fechada | B23: Soma dos tratamentos fechados na semana. Uso interno: nunca divulgue valores ao paciente.
A24: Investimento | B24: Só anúncios (Meta, Google). Por isso CPL, CAC e ROAS aqui são “só anúncios”. Para o CAC real, com agência e equipe, use a Calculadora de CAC.
A26: Exemplo de linha
A27: Semana (início) | B27: Canal | C27: Investimento | D27: Leads | E27: Qualificados | F27: Agendados | G27: Compareceram | H27: Fechados | I27: Receita fechada
A28: 46272 | B28: Meta | C28: 450 | D28: 42 | E28: 14 | F28: 5 | G28: 3 | H28: 1 | I28: 350
A29: Exemplo apenas para mostrar o formato; não entra nos cálculos.

Sheet Entrada semanal
A2: Entrada semanal
A3: Uma linha por semana por canal. Preencha só as células douradas.
A4: Semana (início) | B4: Canal | C4: Investimento | D4: Leads | E4: Qualificados | F4: Agendados | G4: Compareceram | H4: Fechados | I4: Receita fechada | J4: Verificação
J5: =IF(A5="","",IF(AND(D5>=E5,E5>=F5,F5>=G5,G5>=H5),"ok","confira o funil"))
J6: =IF(A6="","",IF(AND(D6>=E6,E6>=F6,F6>=G6,G6>=H6),"ok","confira o funil"))
J7: =IF(A7="","",IF(AND(D7>=E7,E7>=F7,F7>=G7,G7>=H7),"ok","confira o funil"))
J8: =IF(A8="","",IF(AND(D8>=E8,E8>=F8,F8>=G8,G8>=H8),"ok","confira o funil"))
J9: =IF(A9="","",IF(AND(D9>=E9,E9>=F9,F9>=G9,G9>=H9),"ok","confira o funil"))
J10: =IF(A10="","",IF(AND(D10>=E10,E10>=F10,F10>=G10,G10>=H10),"ok","confira o funil"))
J11: =IF(A11="","",IF(AND(D11>=E11,E11>=F11,F11>=G11,G11>=H11),"ok","confira o funil"))
J12: =IF(A12="","",IF(AND(D12>=E12,E12>=F12,F12>=G12,G12>=H12),"ok","confira o funil"))
J13: =IF(A13="","",IF(AND(D13>=E13,E13>=F13,F13>=G13,G13>=H13),"ok","confira o funil"))
J14: =IF(A14="","",IF(AND(D14>=E14,E14>=F14,F14>=G14,G14>=H14),"ok","confira o funil"))
J15: =IF(A15="","",IF(AND(D15>=E15,E15>=F15,F15>=G15,G15>=H15),"ok","confira o funil"))
J16: =IF(A16="","",IF(AND(D16>=E16,E16>=F16,F16>=G16,G16>=H16),"ok","confira o funil"))
... J404: =IF(A404="","",IF(AND(D404>=E404,E404>=F404,F404>=G404,G404>=H404),"ok","confira o funil"))

Sheet Dashboard
A2: Dashboard da clínica
A3: Última semana lançada | B3: =MAX(e_semana) -> 00:00:00 | C3: Primeira semana | D3: =MIN(e_semana) -> 00:00:00
A5: Período | B5: Investimento (anúncios) | C5: Leads qualificados | D5: Consultas agendadas | E5: Receita fechada | G5: De | H5: Até | I5: Semanas
A6: Última semana | B6: =B11 -> 0 | C6: =B13 -> 0 | D6: =B14 -> 0 | E6: =B17 -> 0 | G6: =$B$3 -> 00:00:00 | H6: =$B$3 -> 00:00:00 | I6: =IF($B$3=0,0,1) -> 0
A7: Média 4 semanas | B7: =IFERROR(C11/$I$7,0) -> 0 | C7: =IFERROR(C13/$I$7,0) -> 0 | D7: =IFERROR(C14/$I$7,0) -> 0 | E7: =IFERROR(C17/$I$7,0) -> 0 | G7: =IF($B$3=0,0,$B$3-21) -> 00:00:00 | H7: =$B$3 -> 00:00:00 | I7: =IF($B$3=0,0,MIN(4,($B$3-$D$3)/7+1)) -> 0
A8: Mês até agora | B8: =D11 -> 0 | C8: =D13 -> 0 | D8: =D14 -> 0 | E8: =D17 -> 0 | G8: =IF($B$3=0,0,DATE(YEAR($B$3),MONTH($B$3),1)) -> 00:00:00 | H8: =$B$3 -> 00:00:00 | I8: =IF($B$3=0,0,INT(($B$3-MAX($G$8,$D$3))/7)+1) -> 0
A10: Totais do período | B10: Última semana | C10: Últimas 4 semanas | D10: Mês até agora
A11: Investimento (anúncios) | B11: =SUMIFS(e_invest,e_semana,">="&$G$6,e_semana,"<="&$H$6) -> 0 | C11: =SUMIFS(e_invest,e_semana,">="&$G$7,e_semana,"<="&$H$7) -> 0 | D11: =SUMIFS(e_invest,e_semana,">="&$G$8,e_semana,"<="&$H$8) -> 0
A12: Leads | B12: =SUMIFS(e_leads,e_semana,">="&$G$6,e_semana,"<="&$H$6) -> 0 | C12: =SUMIFS(e_leads,e_semana,">="&$G$7,e_semana,"<="&$H$7) -> 0 | D12: =SUMIFS(e_leads,e_semana,">="&$G$8,e_semana,"<="&$H$8) -> 0
A13: Leads qualificados | B13: =SUMIFS(e_qual,e_semana,">="&$G$6,e_semana,"<="&$H$6) -> 0 | C13: =SUMIFS(e_qual,e_semana,">="&$G$7,e_semana,"<="&$H$7) -> 0 | D13: =SUMIFS(e_qual,e_semana,">="&$G$8,e_semana,"<="&$H$8) -> 0
A14: Consultas agendadas | B14: =SUMIFS(e_agend,e_semana,">="&$G$6,e_semana,"<="&$H$6) -> 0 | C14: =SUMIFS(e_agend,e_semana,">="&$G$7,e_semana,"<="&$H$7) -> 0 | D14: =SUMIFS(e_agend,e_semana,">="&$G$8,e_semana,"<="&$H$8) -> 0
A15: Comparecimentos | B15: =SUMIFS(e_comp,e_semana,">="&$G$6,e_semana,"<="&$H$6) -> 0 | C15: =SUMIFS(e_comp,e_semana,">="&$G$7,e_semana,"<="&$H$7) -> 0 | D15: =SUMIFS(e_comp,e_semana,">="&$G$8,e_semana,"<="&$H$8) -> 0
A16: Tratamentos fechados | B16: =SUMIFS(e_fech,e_semana,">="&$G$6,e_semana,"<="&$H$6) -> 0 | C16: =SUMIFS(e_fech,e_semana,">="&$G$7,e_semana,"<="&$H$7) -> 0 | D16: =SUMIFS(e_fech,e_semana,">="&$G$8,e_semana,"<="&$H$8) -> 0
A17: Receita fechada | B17: =SUMIFS(e_receita,e_semana,">="&$G$6,e_semana,"<="&$H$6) -> 0 | C17: =SUMIFS(e_receita,e_semana,">="&$G$7,e_semana,"<="&$H$7) -> 0 | D17: =SUMIFS(e_receita,e_semana,">="&$G$8,e_semana,"<="&$H$8) -> 0
A19: Indicadores | B19: Última semana | C19: Últimas 4 semanas | D19: Mês até agora | E19: Meta | F19: Melhor se for
A20: CPL (só anúncios) | B20: =IFERROR(B11/B12,"–") -> – | C20: =IFERROR(C11/C12,"–") -> – | D20: =IFERROR(D11/D12,"–") -> – | E20: =IF(Metas!B5="","",Metas!B5) | F20: =Metas!C5 -> menor
A21: Custo por lead qualificado | B21: =IFERROR(B11/B13,"–") -> – | C21: =IFERROR(C11/C13,"–") -> – | D21: =IFERROR(D11/D13,"–") -> – | E21: =IF(Metas!B6="","",Metas!B6) | F21: =Metas!C6 -> menor
A22: Custo por consulta agendada | B22: =IFERROR(B11/B14,"–") -> – | C22: =IFERROR(C11/C14,"–") -> – | D22: =IFERROR(D11/D14,"–") -> – | E22: =IF(Metas!B7="","",Metas!B7) | F22: =Metas!C7 -> menor
A23: Taxa de comparecimento | B23: =IFERROR(B15/B14,"–") -> – | C23: =IFERROR(C15/C14,"–") -> – | D23: =IFERROR(D15/D14,"–") -> – | E23: =IF(Metas!B8="","",Metas!B8) | F23: =Metas!C8 -> maior
A24: Taxa de fechamento | B24: =IFERROR(B16/B15,"–") -> – | C24: =IFERROR(C16/C15,"–") -> – | D24: =IFERROR(D16/D15,"–") -> – | E24: =IF(Metas!B9="","",Metas!B9) | F24: =Metas!C9 -> maior
A25: CAC (só anúncios) | B25: =IFERROR(B11/B16,"–") -> – | C25: =IFERROR(C11/C16,"–") -> – | D25: =IFERROR(D11/D16,"–") -> – | E25: =IF(Metas!B10="","",Metas!B10) | F25: =Metas!C10 -> menor
A26: ROAS (receita ÷ investimento) | B26: =IFERROR(B17/B11,"–") -> – | C26: =IFERROR(C17/C11,"–") -> – | D26: =IFERROR(D17/D11,"–") -> – | E26: =IF(Metas!B11="","",Metas!B11) | F26: =Metas!C11 -> maior
A27: Faixa amarela (tolerância) | B27: =Metas!B13 -> 0.1
A28: Verde: dentro da meta · Amarelo: até a tolerância fora · Vermelho: além disso · Sem cor: sem meta definida.
A30: Tendência semanal (últimas 8 semanas)
A31: Semana | B31: Investimento (anúncios) | C31: Leads qualificados | D31: Consultas agendadas | E31: Receita fechada
A32: =IF($B$3=0,0,$B$3-49) -> 00:00:00 | B32: =IF($A32=0,0,SUMIFS(e_invest,e_semana,$A32)) -> 0 | C32: =IF($A32=0,0,SUMIFS(e_qual,e_semana,$A32)) -> 0 | D32: =IF($A32=0,0,SUMIFS(e_agend,e_semana,$A32)) -> 0 | E32: =IF($A32=0,0,SUMIFS(e_receita,e_semana,$A32)) -> 0
A33: =IF($B$3=0,0,$B$3-42) -> 00:00:00 | B33: =IF($A33=0,0,SUMIFS(e_invest,e_semana,$A33)) -> 0 | C33: =IF($A33=0,0,SUMIFS(e_qual,e_semana,$A33)) -> 0 | D33: =IF($A33=0,0,SUMIFS(e_agend,e_semana,$A33)) -> 0 | E33: =IF($A33=0,0,SUMIFS(e_receita,e_semana,$A33)) -> 0
A34: =IF($B$3=0,0,$B$3-35) -> 00:00:00 | B34: =IF($A34=0,0,SUMIFS(e_invest,e_semana,$A34)) -> 0 | C34: =IF($A34=0,0,SUMIFS(e_qual,e_semana,$A34)) -> 0 | D34: =IF($A34=0,0,SUMIFS(e_agend,e_semana,$A34)) -> 0 | E34: =IF($A34=0,0,SUMIFS(e_receita,e_semana,$A34)) -> 0
A35: =IF($B$3=0,0,$B$3-28) -> 00:00:00 | B35: =IF($A35=0,0,SUMIFS(e_invest,e_semana,$A35)) -> 0 | C35: =IF($A35=0,0,SUMIFS(e_qual,e_semana,$A35)) -> 0 | D35: =IF($A35=0,0,SUMIFS(e_agend,e_semana,$A35)) -> 0 | E35: =IF($A35=0,0,SUMIFS(e_receita,e_semana,$A35)) -> 0
A36: =IF($B$3=0,0,$B$3-21) -> 00:00:00 | B36: =IF($A36=0,0,SUMIFS(e_invest,e_semana,$A36)) -> 0 | C36: =IF($A36=0,0,SUMIFS(e_qual,e_semana,$A36)) -> 0 | D36: =IF($A36=0,0,SUMIFS(e_agend,e_semana,$A36)) -> 0 | E36: =IF($A36=0,0,SUMIFS(e_receita,e_semana,$A36)) -> 0
A37: =IF($B$3=0,0,$B$3-14) -> 00:00:00 | B37: =IF($A37=0,0,SUMIFS(e_invest,e_semana,$A37)) -> 0 | C37: =IF($A37=0,0,SUMIFS(e_qual,e_semana,$A37)) -> 0 | D37: =IF($A37=0,0,SUMIFS(e_agend,e_semana,$A37)) -> 0 | E37: =IF($A37=0,0,SUMIFS(e_receita,e_semana,$A37)) -> 0
A38: =IF($B$3=0,0,$B$3-7) -> 00:00:00 | B38: =IF($A38=0,0,SUMIFS(e_invest,e_semana,$A38)) -> 0 | C38: =IF($A38=0,0,SUMIFS(e_qual,e_semana,$A38)) -> 0 | D38: =IF($A38=0,0,SUMIFS(e_agend,e_semana,$A38)) -> 0 | E38: =IF($A38=0,0,SUMIFS(e_receita,e_semana,$A38)) -> 0
A39: =$B$3 -> 00:00:00 | B39: =IF($A39=0,0,SUMIFS(e_invest,e_semana,$A39)) -> 0 | C39: =IF($A39=0,0,SUMIFS(e_qual,e_semana,$A39)) -> 0 | D39: =IF($A39=0,0,SUMIFS(e_agend,e_semana,$A39)) -> 0 | E39: =IF($A39=0,0,SUMIFS(e_receita,e_semana,$A39)) -> 0
A42: Funil do mês até agora
A43: Etapa | B43: Quantidade | C43: Conversão da etapa anterior
A44: Leads | B44: =D12 -> 0
A45: Qualificados | B45: =D13 -> 0 | C45: =IFERROR(B45/B44,"–") -> –
A46: Agendados | B46: =D14 -> 0 | C46: =IFERROR(B46/B45,"–") -> –
A47: Compareceram | B47: =D15 -> 0 | C47: =IFERROR(B47/B46,"–") -> –
...

Sheet Por canal
A2: Por canal: quem traz receita, não só leads
A3: Período | B3: Mês até agora | C3: de | D3: =IF($B$3="Tudo",Dashboard!$D$3,IF($B$3="Última semana",Dashboard!$G$6,IF($B$3="Últimas 4 semanas",Dashboard!$G$7,Dashboard!$G$8))) -> 00:00:00 | E3: até | F3: =Dashboard!$B$3 -> 00:00:00
A5: Canal | B5: Investimento | C5: Leads | D5: Qualificados | E5: Agendados | F5: Compareceram | G5: Fechados | H5: Receita fechada | I5: CPL | J5: Custo por qualificado | K5: Custo por agendamento | L5: Comparecimento | M5: Fechamento | N5: CAC | O5: ROAS | P5: % dos leads | Q5: % da receita
A6: Meta | B6: =SUMIFS(e_invest,e_canal,$A6,e_semana,">="&$D$3,e_semana,"<="&$F$3) -> 0 | C6: =SUMIFS(e_leads,e_canal,$A6,e_semana,">="&$D$3,e_semana,"<="&$F$3) -> 0 | D6: =SUMIFS(e_qual,e_canal,$A6,e_semana,">="&$D$3,e_semana,"<="&$F$3) -> 0 | E6: =SUMIFS(e_agend,e_canal,$A6,e_semana,">="&$D$3,e_semana,"<="&$F$3) -> 0 | F6: =SUMIFS(e_comp,e_canal,$A6,e_semana,">="&$D$3,e_semana,"<="&$F$3) -> 0 | G6: =SUMIFS(e_fech,e_canal,$A6,e_semana,">="&$D$3,e_semana,"<="&$F$3) -> 0 | H6: =SUMIFS(e_receita,e_canal,$A6,e_semana,">="&$D$3,e_semana,"<="&$F$3) -> 0 | I6: =IFERROR(B6/C6,"–") -> – | J6: =IFERROR(B6/D6,"–") -> – | K6: =IFERROR(B6/E6,"–") -> – | L6: =IFERROR(F6/E6,"–") -> – | M6: =IFERROR(G6/F6,"–") -> – | N6: =IFERROR(B6/G6,"–") -> – | O6: =IFERROR(H6/B6,"–") -> – | P6: =IFERROR(C6/C$12,"–") -> – | Q6: =IFERROR(H6/H$12,"–") -> –
A7: Google | B7: =SUMIFS(e_invest,e_canal,$A7,e_semana,">="&$D$3,e_semana,"<="&$F$3) -> 0 | C7: =SUMIFS(e_leads,e_canal,$A7,e_semana,">="&$D$3,e_semana,"<="&$F$3) -> 0 | D7: =SUMIFS(e_qual,e_canal,$A7,e_semana,">="&$D$3,e_semana,"<="&$F$3) -> 0 | E7: =SUMIFS(e_agend,e_canal,$A7,e_semana,">="&$D$3,e_semana,"<="&$F$3) -> 0 | F7: =SUMIFS(e_comp,e_canal,$A7,e_semana,">="&$D$3,e_semana,"<="&$F$3) -> 0 | G7: =SUMIFS(e_fech,e_canal,$A7,e_semana,">="&$D$3,e_semana,"<="&$F$3) -> 0 | H7: =SUMIFS(e_receita,e_canal,$A7,e_semana,">="&$D$3,e_semana,"<="&$F$3) -> 0 | I7: =IFERROR(B7/C7,"–") -> – | J7: =IFERROR(B7/D7,"–") -> – | K7: =IFERROR(B7/E7,"–") -> – | L7: =IFERROR(F7/E7,"–") -> – | M7: =IFERROR(G7/F7,"–") -> – | N7: =IFERROR(B7/G7,"–") -> – | O7: =IFERROR(H7/B7,"–") -> – | P7: =IFERROR(C7/C$12,"–") -> – | Q7: =IFERROR(H7/H$12,"–") -> –
A8: GBP/orgânico | B8: =SUMIFS(e_invest,e_canal,$A8,e_semana,">="&$D$3,e_semana,"<="&$F$3) -> 0 | C8: =SUMIFS(e_leads,e_canal,$A8,e_semana,">="&$D$3,e_semana,"<="&$F$3) -> 0 | D8: =SUMIFS(e_qual,e_canal,$A8,e_semana,">="&$D$3,e_semana,"<="&$F$3) -> 0 | E8: =SUMIFS(e_agend,e_canal,$A8,e_semana,">="&$D$3,e_semana,"<="&$F$3) -> 0 | F8: =SUMIFS(e_comp,e_canal,$A8,e_semana,">="&$D$3,e_semana,"<="&$F$3) -> 0 | G8: =SUMIFS(e_fech,e_canal,$A8,e_semana,">="&$D$3,e_semana,"<="&$F$3) -> 0 | H8: =SUMIFS(e_receita,e_canal,$A8,e_semana,">="&$D$3,e_semana,"<="&$F$3) -> 0 | I8: =IFERROR(B8/C8,"–") -> – | J8: =IFERROR(B8/D8,"–") -> – | K8: =IFERROR(B8/E8,"–") -> – | L8: =IFERROR(F8/E8,"–") -> – | M8: =IFERROR(G8/F8,"–") -> – | N8: =IFERROR(B8/G8,"–") -> – | O8: =IFERROR(H8/B8,"–") -> – | P8: =IFERROR(C8/C$12,"–") -> – | Q8: =IFERROR(H8/H$12,"–") -> –
A9: Indicação | B9: =SUMIFS(e_invest,e_canal,$A9,e_semana,">="&$D$3,e_semana,"<="&$F$3) -> 0 | C9: =SUMIFS(e_leads,e_canal,$A9,e_semana,">="&$D$3,e_semana,"<="&$F$3) -> 0 | D9: =SUMIFS(e_qual,e_canal,$A9,e_semana,">="&$D$3,e_semana,"<="&$F$3) -> 0 | E9: =SUMIFS(e_agend,e_canal,$A9,e_semana,">="&$D$3,e_semana,"<="&$F$3) -> 0 | F9: =SUMIFS(e_comp,e_canal,$A9,e_semana,">="&$D$3,e_semana,"<="&$F$3) -> 0 | G9: =SUMIFS(e_fech,e_canal,$A9,e_semana,">="&$D$3,e_semana,"<="&$F$3) -> 0 | H9: =SUMIFS(e_receita,e_canal,$A9,e_semana,">="&$D$3,e_semana,"<="&$F$3) -> 0 | I9: =IFERROR(B9/C9,"–") -> – | J9: =IFERROR(B9/D9,"–") -> – | K9: =IFERROR(B9/E9,"–") -> – | L9: =IFERROR(F9/E9,"–") -> – | M9: =IFERROR(G9/F9,"–") -> – | N9: =IFERROR(B9/G9,"–") -> – | O9: =IFERROR(H9/B9,"–") -> – | P9: =IFERROR(C9/C$12,"–") -> – | Q9: =IFERROR(H9/H$12,"–") -> –
A10: Instagram orgânico | B10: =SUMIFS(e_invest,e_canal,$A10,e_semana,">="&$D$3,e_semana,"<="&$F$3) -> 0 | C10: =SUMIFS(e_leads,e_canal,$A10,e_semana,">="&$D$3,e_semana,"<="&$F$3) -> 0 | D10: =SUMIFS(e_qual,e_canal,$A10,e_semana,">="&$D$3,e_semana,"<="&$F$3) -> 0 | E10: =SUMIFS(e_agend,e_canal,$A10,e_semana,">="&$D$3,e_semana,"<="&$F$3) -> 0 | F10: =SUMIFS(e_comp,e_canal,$A10,e_semana,">="&$D$3,e_semana,"<="&$F$3) -> 0 | G10: =SUMIFS(e_fech,e_canal,$A10,e_semana,">="&$D$3,e_semana,"<="&$F$3) -> 0 | H10: =SUMIFS(e_receita,e_canal,$A10,e_semana,">="&$D$3,e_semana,"<="&$F$3) -> 0 | I10: =IFERROR(B10/C10,"–") -> – | J10: =IFERROR(B10/D10,"–") -> – | K10: =IFERROR(B10/E10,"–") -> – | L10: =IFERROR(F10/E10,"–") -> – | M10: =IFERROR(G10/F10,"–") -> – | N10: =IFERROR(B10/G10,"–") -> – | O10: =IFERROR(H10/B10,"–") -> – | P10: =IFERROR(C10/C$12,"–") -> – | Q10: =IFERROR(H10/H$12,"–") -> –
A11: Outro | B11: =SUMIFS(e_invest,e_canal,$A11,e_semana,">="&$D$3,e_semana,"<="&$F$3) -> 0 | C11: =SUMIFS(e_leads,e_canal,$A11,e_semana,">="&$D$3,e_semana,"<="&$F$3) -> 0 | D11: =SUMIFS(e_qual,e_canal,$A11,e_semana,">="&$D$3,e_semana,"<="&$F$3) -> 0 | E11: =SUMIFS(e_agend,e_canal,$A11,e_semana,">="&$D$3,e_semana,"<="&$F$3) -> 0 | F11: =SUMIFS(e_comp,e_canal,$A11,e_semana,">="&$D$3,e_semana,"<="&$F$3) -> 0 | G11: =SUMIFS(e_fech,e_canal,$A11,e_semana,">="&$D$3,e_semana,"<="&$F$3) -> 0 | H11: =SUMIFS(e_receita,e_canal,$A11,e_semana,">="&$D$3,e_semana,"<="&$F$3) -> 0 | I11: =IFERROR(B11/C11,"–") -> – | J11: =IFERROR(B11/D11,"–") -> – | K11: =IFERROR(B11/E11,"–") -> – | L11: =IFERROR(F11/E11,"–") -> – | M11: =IFERROR(G11/F11,"–") -> – | N11: =IFERROR(B11/G11,"–") -> – | O11: =IFERROR(H11/B11,"–") -> – | P11: =IFERROR(C11/C$12,"–") -> – | Q11: =IFERROR(H11/H$12,"–") -> –
A12: Total | B12: =SUM(B6:B11) -> 0 | C12: =SUM(C6:C11) -> 0 | D12: =SUM(D6:D11) -> 0 | E12: =SUM(E6:E11) -> 0 | F12: =SUM(F6:F11) -> 0 | G12: =SUM(G6:G11) -> 0 | H12: =SUM(H6:H11) -> 0 | I12: =IFERROR(B12/C12,"–") -> – | J12: =IFERROR(B12/D12,"–") -> – | K12: =IFERROR(B12/E12,"–") -> – | L12: =IFERROR(F12/E12,"–") -> – | M12: =IFERROR(G12/F12,"–") -> – | N12: =IFERROR(B12/G12,"–") -> – | O12: =IFERROR(H12/B12,"–") -> – | P12: =IFERROR(C12/C$12,"–") -> – | Q12: =IFERROR(H12/H$12,"–") -> –
A14: Leitura: compare “% dos leads” com “% da receita”. Canal com muito lead e pouca receita precisa de qualificação; canal com pouco lead e muita receita merece mais atenção.
A15: CPL, CAC e ROAS aqui consideram só o investimento em anúncios. Canais orgânicos aparecem com custo zero.

Sheet Metas
A2: Metas
A3: Defina as metas da sua clínica. O Dashboard fica verde, amarelo ou vermelho comparando com elas.
A4: Indicador | B4: Meta | C4: Melhor se for | D4: Como pensar a meta
A5: CPL (só anúncios) | C5: menor | D5: Quanto você aceita pagar por um contato.
A6: Custo por lead qualificado | C6: menor | D6: Custo por contato com perfil real.
A7: Custo por consulta agendada | C7: menor | D7: Custo para colocar uma avaliação na agenda.
A8: Taxa de comparecimento | C8: maior | D8: Agendados que vieram. Lembretes melhoram isso.
A9: Taxa de fechamento | C9: maior | D9: Avaliações que viraram tratamento.
A10: CAC (só anúncios) | C10: menor | D10: Custo de anúncios por paciente fechado.
A11: ROAS (receita ÷ investimento) | C11: maior | D11: Receita fechada para cada real em anúncios.
A13: Faixa amarela (tolerância) | B13: 0.1 | D13: Ex.: 10% = amarelo quando está até 10% pior que a meta.
A15: Use os números da sua própria clínica para definir metas. Comece pela média das últimas 4 semanas e busque melhorar um pouco por mês.

Sheet Campanha A vs B
A2: Campanha A vs B: clique barato ≠ paciente barato
A3: Preencha as células douradas de duas campanhas e compare o custo por paciente fechado.
B5: Campanha A | C5: Campanha B
A6: Cliques
A7: CPC (custo por clique)
A8: Pacientes fechados
A9: Receita fechada
A10: Investimento (cliques × CPC) | B10: =B6*B7 -> 0 | C10: =C6*C7 -> 0
A11: Custo por paciente fechado | B11: =IFERROR(B10/B8,"–") -> – | C11: =IFERROR(C10/C8,"–") -> –
A12: ROAS (receita ÷ investimento) | B12: =IFERROR(B9/B10,"–") -> – | C12: =IFERROR(C9/C10,"–") -> –
A14: =IF(OR(B6="",C6=""),"Preencha as duas campanhas para comparar.",IF(AND(ISNUMBER(B11),ISNUMBER(C11)),IF(B11<C11,"A Campanha A traz pacientes mais baratos.",IF(C11<B11,"A Campanha B traz pacientes mais baratos.","Mesmo custo por paciente.")),IF(ISNUMBER(C11),"A Campanha A ainda não fechou paciente: o clique barato não virou paciente.",IF(ISNUMBER(B11),"A Campanha B ainda não fechou paciente: o clique barato não virou paciente.","Nenhuma das campanhas fechou paciente ainda.")))) -> Preencha as duas campanhas para comparar.
A16: Lição: CPC baixo não significa paciente barato. Compare custo por paciente fechado e ROAS, não o custo do clique.
